Workbook

Sheet 總覽
A1: CP 重測追蹤總覽（資料至 2026-10-04 23:59；DailyReport 20260929 / 20261002 / 20261005）
A3: A. 已重測（9/17 後） | B3: 批數 | C3: 平均原良率 (%) | D3: 平均重測良率 (%) | E3: 平均原 DIR0 (%) | F3: 平均重測 DIR0 (%)
A4: 全部 | B4: =COUNTA('已重測_9-17後'!C2:C82) -> 81 | C4: =AVERAGE('已重測_9-17後'!F2:F82) -> 90.687531 | D4: =AVERAGE('已重測_9-17後'!J2:J82) -> 94.790741 | E4: =AVERAGE('已重測_9-17後'!G2:G82) -> 5.5072298 | F4: =AVERAGE('已重測_9-17後'!K2:K82) -> 1.3850661
A6: B. 異常期未重測（9/4 19:00 ~ 9/17 12:00，1003） | B6: 批數 | C6: 平均良率 (%) | D6: DIR0 > 5% 批數 | E6: DIR0 > 8% 批數 | F6: DIR0 加權 (%)
A7: 50A / 550mV | B7: =COUNTA(未重測_50A_550mV!C2:C46) -> 45 | C7: =AVERAGE(未重測_50A_550mV!H2:H46) -> 90.587556 | D7: =COUNTIF(未重測_50A_550mV!J2:J46,">5") -> 16 | E7: =COUNTIF(未重測_50A_550mV!J2:J46,">8") -> 4 | F7: =SUM(未重測_50A_550mV!I2:I46)/SUM(未重測_50A_550mV!G2:G46)*100 -> 5.267953
A8: 50A / 530mV（不需重測） | B8: =COUNTA(未重測_50A_530mV!C2:C45) -> 44 | C8: =AVERAGE(未重測_50A_530mV!H2:H45) -> 94.179091 | D8: =COUNTIF(未重測_50A_530mV!J2:J45,">5") -> 0 | E8: =COUNTIF(未重測_50A_530mV!J2:J45,">8") -> 0 | F8: =SUM(未重測_50A_530mV!I2:I45)/SUM(未重測_50A_530mV!G2:G45)*100 -> 1.8985798
A9: 35A / 570mV | B9: 0（15 批已全數重測）
A11: C. 50A/550mV 切割推估 | B11: 批數 | C11: 平均良率 (%) | D11: DIR0 > 5% 批數 | E11: DIR0 > 8% 批數 | F11: DIR0 加權 (%)
A12: A 較可能已切割 | B12: =COUNTIF(未重測_50A_550mV!K2:K46,"A 較可能已切割（批號 < 同型號最小已重測批號）") -> 14 | C12: =AVERAGEIFS(未重測_50A_550mV!H2:H46,未重測_50A_550mV!K2:K46,"A 較可能已切割（批號 < 同型號最小已重測批號）") -> 90.340714 | D12: =COUNTIFS(未重測_50A_550mV!K2:K46,"A 較可能已切割（批號 < 同型號最小已重測批號）",未重測_50A_550mV!J2:J46,">5") -> 3 | E12: =COUNTIFS(未重測_50A_550mV!K2:K46,"A 較可能已切割（批號 < 同型號最小已重測批號）",未重測_50A_550mV!J2:J46,">8") -> 0 | F12: =SUMIFS(未重測_50A_550mV!I2:I46,未重測_50A_550mV!K2:K46,"A 較可能已切割（批號 < 同型號最小已重測批號）")/SUMIFS(未重測_50A_550mV!G2:G46,未重測_50A_550mV!K2:K46,"A 較可能已切割（批號 < 同型號最小已重測批號）")*100 -> 4.6711556
A13: B 可能未切割（在已重測範圍內） | B13: =COUNTIF(未重測_50A_550mV!K2:K46,"B 可能未切割（批號在已重測範圍內）") -> 21 | C13: =AVERAGEIFS(未重測_50A_550mV!H2:H46,未重測_50A_550mV!K2:K46,"B 可能未切割（批號在已重測範圍內）") -> 91.57619 | D13: =COUNTIFS(未重測_50A_550mV!K2:K46,"B 可能未切割（批號在已重測範圍內）",未重測_50A_550mV!J2:J46,">5") -> 6 | E13: =COUNTIFS(未重測_50A_550mV!K2:K46,"B 可能未切割（批號在已重測範圍內）",未重測_50A_550mV!J2:J46,">8") -> 1 | F13: =SUMIFS(未重測_50A_550mV!I2:I46,未重測_50A_550mV!K2:K46,"B 可能未切割（批號在已重測範圍內）")/SUMIFS(未重測_50A_550mV!G2:G46,未重測_50A_550mV!K2:K46,"B 可能未切割（批號在已重測範圍內）")*100 -> 4.9585275
A14: C 可能未切割（批號較新） | B14: =COUNTIF(未重測_50A_550mV!K2:K46,"C 可能未切割（批號 > 已重測最大批號）") -> 9 | C14: =AVERAGEIFS(未重測_50A_550mV!H2:H46,未重測_50A_550mV!K2:K46,"C 可能未切割（批號 > 已重測最大批號）") -> 88.81 | D14: =COUNTIFS(未重測_50A_550mV!K2:K46,"C 可能未切割（批號 > 已重測最大批號）",未重測_50A_550mV!J2:J46,">5") -> 7 | E14: =COUNTIFS(未重測_50A_550mV!K2:K46,"C 可能未切割（批號 > 已重測最大批號）",未重測_50A_550mV!J2:J46,">8") -> 3 | F14: =SUMIFS(未重測_50A_550mV!I2:I46,未重測_50A_550mV!K2:K46,"C 可能未切割（批號 > 已重測最大批號）")/SUMIFS(未重測_50A_550mV!G2:G46,未重測_50A_550mV!K2:K46,"C 可能未切割（批號 > 已重測最大批號）")*100 -> 6.9616588
A15: 無參考 | B15: =COUNTIF(未重測_50A_550mV!K2:K46,"無參考（同前綴無已重測批）") -> 1 | C15: =AVERAGEIFS(未重測_50A_550mV!H2:H46,未重測_50A_550mV!K2:K46,"無參考（同前綴無已重測批）") -> 89.28 | D15: =COUNTIFS(未重測_50A_550mV!K2:K46,"無參考（同前綴無已重測批）",未重測_50A_550mV!J2:J46,">5") -> 0 | E15: =COUNTIFS(未重測_50A_550mV!K2:K46,"無參考（同前綴無已重測批）",未重測_50A_550mV!J2:J46,">8") -> 0 | F15: =SUMIFS(未重測_50A_550mV!I2:I46,未重測_50A_550mV!K2:K46,"無參考（同前綴無已重測批）")/SUMIFS(未重測_50A_550mV!G2:G46,未重測_50A_550mV!K2:K46,"無參考（同前綴無已重測批）")*100 -> 4.6619718
A17: 說明
A18: 1. 同批號以 Input (pcs) 達多數片的列為主；1 片補測列不納入。良率為 Initial CP yield。DIR0 fail rate = DIR0 fail dies ÷ Total in。
A19: 2. 切割推估依批號順序：以同型號已重測批號範圍（50A/550mV：RK32330 ~ RK32476；EK 僅 EK58925）為參考，批號較小者較早投入、較可能已切割。為經驗推估，需至 MES 確認。
A20: 3. 未重測的 50A/550mV 中有 36 批原測於 9/4 ~ 9/6，也可能已切割或被擱置，需向現場確認。
A21: 4. 新增 3 批重測（RK32383 / RK32413 / RK32414，10/3 於 2101）重測後 DIR0 仍有 2.6~4.6%，增益 +2.7~+3.6 pt，低於先前平均。
A23: D. 切割推估：A / B / C 如何區分
A24: 以「同 Type(A) + Type(mV) + 批號前綴」為一組，取該組已重測批號的最小與最大值，再比較每個未重測批的批號位置。50A/550mV 的 RK 組已重測範圍為 RK32330 ~ RK32476（EK 組僅 EK58925，NK 組無已重測批）。前提：批號越小越早投入、越早進入後段製程（含切割），為推論；批號與原測時間並非嚴格同序；B / C 不保證仍有 wafer。
A25: 類別 | B25: 條件 | C25: 推論 | D25: 批數
A26: A 較可能已切割 | B26: 批號 < 最小已重測批號（RK < 32330） | C26: 批號小、較早投入，流程可能已走到切割 | D26: =COUNTIF(未重測_50A_550mV!K2:K46,"A*") -> 14
A27: B 可能仍可重測 | B27: 批號落在已重測範圍內（RK32330 ~ 32476） | C27: 前後批都能重測，可能只是尚未輪到 | D27: =COUNTIF(未重測_50A_550mV!K2:K46,"B*") -> 21
A28: C 可能仍可重測 | B28: 批號 > 最大已重測批號（RK > 32476、EK58927/58928） | C28: 批號較新，流程較前面，較不可能已切割 | D28: =COUNTIF(未重測_50A_550mV!K2:K46,"C*") -> 9
A29: 無參考 | B29: 同前綴沒有已重測批（NK14045） | C29: 無法比較 | D29: =COUNTIF(未重測_50A_550mV!K2:K46,"無參考*") -> 1

Sheet 未重測_50A_550mV
A1: Type(A) | B1: Type(mV) | C1: 批號 | D1: 原測機台 | E1: 原測時間 | F1: Input (pcs) | G1: Total in (dies) | H1: Initial CP yield (%) | I1: DIR0 fail (dies) | J1: DIR0 fail rate (%) | K1: 切割推估 | L1: 備註
A2: 50A | B2: 550MV | C2: EK58927 | D2: 3380P-ATE-1003 | E2: 46270.887 | F2: 25 | G2: 14200 | H2: 93.26 | I2: 601 | J2: =I2/G2*100 -> 4.2323944 | K2: C 可能未切割（批號 > 已重測最大批號）
A3: 50A | B3: 550MV | C3: EK58928 | D3: 3380P-ATE-1003 | E3: 46271.547 | F3: 25 | G3: 14200 | H3: 92.92 | I3: 642 | J3: =I3/G3*100 -> 4.5211268 | K3: C 可能未切割（批號 > 已重測最大批號）
A4: 50A | B4: 550MV | C4: NK14045 | D4: 3380P-ATE-1003 | E4: 46271.651 | F4: 25 | G4: 14200 | H4: 89.28 | I4: 662 | J4: =I4/G4*100 -> 4.6619718 | K4: 無參考（同前綴無已重測批）
A5: 50A | B5: 550MV | C5: RK32295 | D5: 3380P-ATE-1003 | E5: 46270.459 | F5: 23 | G5: 13064 | H5: 90.28 | I5: 578 | J5: =I5/G5*100 -> 4.4243723 | K5: A 較可能已切割（批號 < 同型號最小已重測批號）
A6: 50A | B6: 550MV | C6: RK32308 | D6: 3380P-ATE-1003 | E6: 46270.564 | F6: 25 | G6: 14200 | H6: 89.15 | I6: 667 | J6: =I6/G6*100 -> 4.6971831 | K6: A 較可能已切割（批號 < 同型號最小已重測批號）
A7: 50A | B7: 550MV | C7: RK32309 | D7: 3380P-ATE-1003 | E7: 46270.305 | F7: 25 | G7: 14200 | H7: 90.29 | I7: 639 | J7: =I7/G7*100 -> 4.5 | K7: A 較可能已切割（批號 < 同型號最小已重測批號）
A8: 50A | B8: 550MV | C8: RK32310 | D8: 3380P-ATE-1003 | E8: 46270.511 | F8: 24 | G8: 13632 | H8: 89.95 | I8: 686 | J8: =I8/G8*100 -> 5.032277 | K8: A 較可能已切割（批號 < 同型號最小已重測批號） | L8: DIR0 > 5%
A9: 50A | B9: 550MV | C9: RK32317 | D9: 3380P-ATE-1003 | E9: 46270.152 | F9: 25 | G9: 14200 | H9: 89.01 | I9: 679 | J9: =I9/G9*100 -> 4.7816901 | K9: A 較可能已切割（批號 < 同型號最小已重測批號）
A10: 50A | B10: 550MV | C10: RK32318 | D10: 3380P-ATE-1003 | E10: 46270.095 | F10: 25 | G10: 14200 | H10: 90.57 | I10: 665 | J10: =I10/G10*100 -> 4.6830986 | K10: A 較可能已切割（批號 < 同型號最小已重測批號）
A11: 50A | B11: 550MV | C11: RK32319 | D11: 3380P-ATE-1003 | E11: 46269.878 | F11: 25 | G11: 14200 | H11: 90.7 | I11: 591 | J11: =I11/G11*100 -> 4.1619718 | K11: A 較可能已切割（批號 < 同型號最小已重測批號）
A12: 50A | B12: 550MV | C12: RK32320 | D12: 3380P-ATE-1003 | E12: 46269.982 | F12: 25 | G12: 14200 | H12: 91.12 | I12: 664 | J12: =I12/G12*100 -> 4.6760563 | K12: A 較可能已切割（批號 < 同型號最小已重測批號）
A13: 50A | B13: 550MV | C13: RK32321 | D13: 3380P-ATE-1003 | E13: 46269.819 | F13: 25 | G13: 14200 | H13: 91.06 | I13: 580 | J13: =I13/G13*100 -> 4.084507 | K13: A 較可能已切割（批號 < 同型號最小已重測批號）
A14: 50A | B14: 550MV | C14: RK32322 | D14: 3380P-ATE-1003 | E14: 46270.034 | F14: 25 | G14: 14200 | H14: 91.41 | I14: 554 | J14: =I14/G14*100 -> 3.9014085 | K14: A 較可能已切割（批號 < 同型號最小已重測批號）
A15: 50A | B15: 550MV | C15: RK32323 | D15: 3380P-ATE-1003 | E15: 46270.197 | F15: 21 | G15: 11928 | H15: 91.92 | I15: 468 | J15: =I15/G15*100 -> 3.9235412 | K15: A 較可能已切割（批號 < 同型號最小已重測批號）
A16: 50A | B16: 550MV | C16: RK32324 | D16: 3380P-ATE-1003 | E16: 46270.253 | F16: 24 | G16: 13632 | H16: 86.17 | I16: 806 | J16: =I16/G16*100 -> 5.9125587 | K16: A 較可能已切割（批號 < 同型號最小已重測批號） | L16: DIR0 > 5%
A17: 50A | B17: 550MV | C17: RK32327 | D17: 3380P-ATE-1003 | E17: 46271.086 | F17: 25 | G17: 14200 | H17: 90.77 | I17: 833 | J17: =I17/G17*100 -> 5.8661972 | K17: A 較可能已切割（批號 < 同型號最小已重測批號） | L17: DIR0 > 5%
A18: 50A | B18: 550MV | C18: RK32328 | D18: 3380P-ATE-1003 | E18: 46270.99 | F18: 25 | G18: 14200 | H18: 92.37 | I18: 664 | J18: =I18/G18*100 -> 4.6760563 | K18: A 較可能已切割（批號 < 同型號最小已重測批號）
A19: 50A | B19: 550MV | C19: RK32331 | D19: 3380P-ATE-1003 | E19: 46270.358 | F19: 25 | G19: 14200 | H19: 90.64 | I19: 545 | J19: =I19/G19*100 -> 3.8380282 | K19: B 可能未切割（批號在已重測範圍內）
A20: 50A | B20: 550MV | C20: RK32335 | D20: 3380P-ATE-1003 | E20: 46269.93 | F20: 25 | G20: 14200 | H20: 90.46 | I20: 565 | J20: =I20/G20*100 -> 3.9788732 | K20: B 可能未切割（批號在已重測範圍內）
A21: 50A | B21: 550MV | C21: RK32337 | D21: 3380P-ATE-1003 | E21: 46270.623 | F21: 24 | G21: 13632 | H21: 91.15 | I21: 543 | J21: =I21/G21*100 -> 3.9832746 | K21: B 可能未切割（批號在已重測範圍內）
A22: 50A | B22: 550MV | C22: RK32338 | D22: 3380P-ATE-1003 | E22: 46270.411 | F22: 25 | G22: 14200 | H22: 93.16 | I22: 508 | J22: =I22/G22*100 -> 3.5774648 | K22: B 可能未切割（批號在已重測範圍內）
A23: 50A | B23: 550MV | C23: RK32339 | D23: 3380P-ATE-1003 | E23: 46271.497 | F23: 25 | G23: 14200 | H23: 90.7 | I23: 847 | J23: =I23/G23*100 -> 5.9647887 | K23: B 可能未切割（批號在已重測範圍內） | L23: DIR0 > 5%
A24: 50A | B24: 550MV | C24: RK32340 | D24: 3380P-ATE-1003 | E24: 46271.75 | F24: 25 | G24: 14200 | H24: 92.13 | I24: 658 | J24: =I24/G24*100 -> 4.6338028 | K24: B 可能未切割（批號在已重測範圍內）
A25: 50A | B25: 550MV | C25: RK32343 | D25: 3380P-ATE-1003 | E25: 46270.789 | F25: 25 | G25: 14200 | H25: 92.95 | I25: 620 | J25: =I25/G25*100 -> 4.3661972 | K25: B 可能未切割（批號在已重測範圍內）
A26: 50A | B26: 550MV | C26: RK32348 | D26: 3380P-ATE-1003 | E26: 46271.449 | F26: 24 | G26: 13632 | H26: 92.44 | I26: 632 | J26: =I26/G26*100 -> 4.6361502 | K26: B 可能未切割（批號在已重測範圍內）
A27: 50A | B27: 550MV | C27: RK32349 | D27: 3380P-ATE-1003 | E27: 46271.643 | F27: 25 | G27: 14200 | H27: 92.92 | I27: 654 | J27: =I27/G27*100 -> 4.6056338 | K27: B 可能未切割（批號在已重測範圍內）
A28: 50A | B28: 550MV | C28: RK32351 | D28: 3380P-ATE-1003 | E28: 46271.7 | F28: 25 | G28: 14200 | H28: 91.85 | I28: 703 | J28: =I28/G28*100 -> 4.9507042 | K28: B 可能未切割（批號在已重測範圍內）
A29: 50A | B29: 550MV | C29: RK32353 | D29: 3380P-ATE-1003 | E29: 46271.201 | F29: 25 | G29: 14200 | H29: 93.39 | I29: 548 | J29: =I29/G29*100 -> 3.8591549 | K29: B 可能未切割（批號在已重測範圍內）
A30: 50A | B30: 550MV | C30: RK32355 | D30: 3380P-ATE-1003 | E30: 46271.152 | F30: 25 | G30: 14200 | H30: 91.87 | I30: 740 | J30: =I30/G30*100 -> 5.2112676 | K30: B 可能未切割（批號在已重測範圍內） | L30: DIR0 > 5%
A31: 50A | B31: 550MV | C31: RK32356 | D31: 3380P-ATE-1003 | E31: 46270.837 | F31: 25 | G31: 14200 | H31: 93.27 | I31: 628 | J31: =I31/G31*100 -> 4.4225352 | K31: B 可能未切割（批號在已重測範圍內）
A32: 50A | B32: 550MV | C32: RK32358 | D32: 3380P-ATE-1003 | E32: 46271.305 | F32: 25 | G32: 14200 | H32: 91.51 | I32: 726 | J32: =I32/G32*100 -> 5.1126761 | K32: B 可能未切割（批號在已重測範圍內） | L32: DIR0 > 5%
A33: 50A | B33: 550MV | C33: RK32360 | D33: 3380P-ATE-1003 | E33: 46271.038 | F33: 25 | G33: 14200 | H33: 92.82 | I33: 624 | J33: =I33/G33*100 -> 4.3943662 | K33: B 可能未切割（批號在已重測範圍內）
A34: 50A | B34: 550MV | C34: RK32372 | D34: 3380P-ATE-1003 | E34: 46271.403 | F34: 25 | G34: 14200 | H34: 91.51 | I34: 764 | J34: =I34/G34*100 -> 5.3802817 | K34: B 可能未切割（批號在已重測範圍內） | L34: DIR0 > 5%
A35: 50A | B35: 550MV | C35: RK32373 | D35: 3380P-ATE-1003 | E35: 46271.25 | F35: 25 | G35: 14200 | H35: 93.13 | I35: 671 | J35: =I35/G35*100 -> 4.7253521 | K35: B 可能未切割（批號在已重測範圍內）
A36: 50A | B36: 550MV | C36: RK32377 | D36: 3380P-ATE-1003 | E36: 46271.595 | F36: 25 | G36: 14200 | H36: 93.93 | I36: 583 | J36: =I36/G36*100 -> 4.1056338 | K36: B 可能未切割（批號在已重測範圍內）
A37: 50A | B37: 550MV | C37: RK32378 | D37: 3380P-ATE-1003 | E37: 46271.354 | F37: 25 | G37: 14200 | H37: 92.62 | I37: 704 | J37: =I37/G37*100 -> 4.9577465 | K37: B 可能未切割（批號在已重測範圍內）
A38: 50A | B38: 550MV | C38: RK32407 | D38: 3380P-ATE-1003 | E38: 46279.799 | F38: 25 | G38: 14200 | H38: 85.23 | I38: 882 | J38: =I38/G38*100 -> 6.2112676 | K38: B 可能未切割（批號在已重測範圍內） | L38: DIR0 > 5%
A39: 50A | B39: 550MV | C39: RK32435 | D39: 3380P-ATE-1003 | E39: 46281.887 | F39: 25 | G39: 14200 | H39: 85.42 | I39: 1585 | J39: =I39/G39*100 -> 11.161972 | K39: B 可能未切割（批號在已重測範圍內） | L39: DIR0 > 8%，建議最優先重測
A40: 50A | B40: 550MV | C40: RK32478 | D40: 3380P-ATE-1003 | E40: 46278.032 | F40: 25 | G40: 14200 | H40: 89.56 | I40: 815 | J40: =I40/G40*100 -> 5.7394366 | K40: C 可能未切割（批號 > 已重測最大批號） | L40: DIR0 > 5%
...

Sheet 未重測_50A_530mV
A1: Type(A) | B1: Type(mV) | C1: 批號 | D1: 原測機台 | E1: 原測時間 | F1: Input (pcs) | G1: Total in (dies) | H1: Initial CP yield (%) | I1: DIR0 fail (dies) | J1: DIR0 fail rate (%) | K1: 切割推估 | L1: 備註
A2: 50A | B2: 530MV | C2: RK32229 | D2: 3380P-ATE-1003 | E2: 46282.206 | F2: 25 | G2: 14200 | H2: 96.96 | I2: 106 | J2: =I2/G2*100 -> 0.74647887 | K2: 不需重測（DIR0 正常）
A3: 50A | B3: 530MV | C3: RK32281 | D3: 3380P-ATE-1003 | E3: 46271.907 | F3: 24 | G3: 13632 | H3: 95.85 | I3: 270 | J3: =I3/G3*100 -> 1.9806338 | K3: 不需重測（DIR0 正常）
A4: 50A | B4: 530MV | C4: RK32282 | D4: 3380P-ATE-1003 | E4: 46272.281 | F4: 25 | G4: 14200 | H4: 95.51 | I4: 329 | J4: =I4/G4*100 -> 2.3169014 | K4: 不需重測（DIR0 正常）
A5: 50A | B5: 530MV | C5: RK32283 | D5: 3380P-ATE-1003 | E5: 46271.858 | F5: 25 | G5: 14200 | H5: 95.38 | I5: 334 | J5: =I5/G5*100 -> 2.3521127 | K5: 不需重測（DIR0 正常）
A6: 50A | B6: 530MV | C6: RK32284 | D6: 3380P-ATE-1003 | E6: 46272.435 | F6: 24 | G6: 13632 | H6: 95.86 | I6: 260 | J6: =I6/G6*100 -> 1.907277 | K6: 不需重測（DIR0 正常）
A7: 50A | B7: 530MV | C7: RK32297 | D7: 3380P-ATE-1003 | E7: 46271.804 | F7: 25 | G7: 14200 | H7: 96.23 | I7: 242 | J7: =I7/G7*100 -> 1.7042254 | K7: 不需重測（DIR0 正常）
A8: 50A | B8: 530MV | C8: RK32298 | D8: 3380P-ATE-1003 | E8: 46271.959 | F8: 25 | G8: 14200 | H8: 94.85 | I8: 337 | J8: =I8/G8*100 -> 2.3732394 | K8: 不需重測（DIR0 正常）
A9: 50A | B9: 530MV | C9: RK32299 | D9: 3380P-ATE-1003 | E9: 46272.225 | F9: 25 | G9: 14200 | H9: 95.22 | I9: 307 | J9: =I9/G9*100 -> 2.1619718 | K9: 不需重測（DIR0 正常）
A10: 50A | B10: 530MV | C10: RK32300 | D10: 3380P-ATE-1003 | E10: 46272.511 | F10: 25 | G10: 14200 | H10: 93.87 | I10: 268 | J10: =I10/G10*100 -> 1.8873239 | K10: 不需重測（DIR0 正常）
A11: 50A | B11: 530MV | C11: RK32301 | D11: 3380P-ATE-1003 | E11: 46272.387 | F11: 25 | G11: 14200 | H11: 95.06 | I11: 340 | J11: =I11/G11*100 -> 2.3943662 | K11: 不需重測（DIR0 正常）
A12: 50A | B12: 530MV | C12: RK32311 | D12: 3380P-ATE-1003 | E12: 46272.069 | F12: 25 | G12: 14200 | H12: 94.15 | I12: 403 | J12: =I12/G12*100 -> 2.8380282 | K12: 不需重測（DIR0 正常）
A13: 50A | B13: 530MV | C13: RK32312 | D13: 3380P-ATE-1003 | E13: 46272.174 | F13: 25 | G13: 14200 | H13: 96 | I13: 271 | J13: =I13/G13*100 -> 1.9084507 | K13: 不需重測（DIR0 正常）
... A45: 50A | B45: 530MV | C45: RK32634 | D45: 3380P-ATE-1003 | E45: 46276.568 | F45: 25 | G45: 14200 | H45: 87.89 | I45: 370 | J45: =I45/G45*100 -> 2.6056338 | K45: 不需重測（DIR0 正常）

Sheet 已重測_9-17後
A1: Type(A) | B1: Type(mV) | C1: 批號 | D1: 原測時間 | E1: 原測機台 | F1: 原測良率 (%) | G1: 原 DIR0 (%) | H1: 重測時間 | I1: 重測機台 | J1: 重測良率 (%) | K1: 重測 DIR0 (%) | L1: 良率變化 (pt) | M1: DIR0 變化 (pt)
A2: 50A | B2: 550MV | C2: RK32344 | D2: 46273.022 | E2: 1003 | F2: 92.93 | G2: 4.4295775 | H2: 46283.932 | I2: 1003 | J2: 95.96 | K2: 1.3873239 | L2: =J2-F2 -> 3.03 | M2: =K2-G2 -> -3.0422535
A3: 50A | B3: 550MV | C3: RK32369 | D3: 46273.286 | E3: 1003 | F3: 91.37 | G3: 4.7887324 | H3: 46283.98 | I3: 1003 | J3: 94.7 | K3: 1.4366197 | L3: =J3-F3 -> 3.33 | M3: =K3-G3 -> -3.3521127
A4: 50A | B4: 550MV | C4: RK32341 | D4: 46272.409 | E4: 1003 | F4: 89.68 | G4: 6.4084507 | H4: 46284.033 | I4: 1003 | J4: 92.53 | K4: 1.2112676 | L4: =J4-F4 -> 2.85 | M4: =K4-G4 -> -5.1971831
A5: 50A | B5: 550MV | C5: RK32354 | D5: 46273.391 | E5: 1003 | F5: 84.02 | G5: 5.2663809 | H5: 46284.079 | I5: 1003 | J5: 87.58 | K5: 1.3242498 | L5: =J5-F5 -> 3.56 | M5: =K5-G5 -> -3.942131
A6: 50A | B6: 550MV | C6: RK32350 | D6: 46272.813 | E6: 1003 | F6: 92.23 | G6: 4.7605634 | H6: 46284.134 | I6: 1003 | J6: 95.82 | K6: 1.1478873 | L6: =J6-F6 -> 3.59 | M6: =K6-G6 -> -3.6126761
A7: 50A | B7: 550MV | C7: RK32371 | D7: 46273.181 | E7: 1003 | F7: 91.38 | G7: 4.7957746 | H7: 46284.182 | I7: 1003 | J7: 94.9 | K7: 1.3309859 | L7: =J7-F7 -> 3.52 | M7: =K7-G7 -> -3.4647887
A8: 50A | B8: 550MV | C8: RK32357 | D8: 46273.074 | E8: 1003 | F8: 92.29 | G8: 4.584507 | H8: 46284.232 | I8: 1003 | J8: 95.83 | K8: 1.056338 | L8: =J8-F8 -> 3.54 | M8: =K8-G8 -> -3.528169
A9: 50A | B9: 550MV | C9: RK32361 | D9: 46272.76 | E9: 1003 | F9: 91.61 | G9: 5.0070423 | H9: 46284.281 | I9: 1003 | J9: 95.44 | K9: 1.1901408 | L9: =J9-F9 -> 3.83 | M9: =K9-G9 -> -3.8169014
A10: 50A | B10: 550MV | C10: RK32448 | D10: 46273.129 | E10: 1003 | F10: 90.85 | G10: 4.7042254 | H10: 46284.33 | I10: 1003 | J10: 94.05 | K10: 1.1197183 | L10: =J10-F10 -> 3.2 | M10: =K10-G10 -> -3.584507
A11: 50A | B11: 550MV | C11: RK32359 | D11: 46272.866 | E11: 1003 | F11: 89.52 | G11: 4.7253521 | H11: 46287.14 | I11: 1003 | J11: 92.72 | K11: 1.4859155 | L11: =J11-F11 -> 3.2 | M11: =K11-G11 -> -3.2394366
A12: 50A | B12: 550MV | C12: RK32370 | D12: 46272.97 | E12: 1003 | F12: 90.57 | G12: 4.6971831 | H12: 46287.189 | I12: 1003 | J12: 93.88 | K12: 1.3873239 | L12: =J12-F12 -> 3.31 | M12: =K12-G12 -> -3.3098592
A13: 50A | B13: 550MV | C13: RK32374 | D13: 46273.338 | E13: 1003 | F13: 92.64 | G13: 4.5352113 | H13: 46287.238 | I13: 1003 | J13: 95.87 | K13: 1.2816901 | L13: =J13-F13 -> 3.23 | M13: =K13-G13 -> -3.2535211
... A82: 50A | B82: 550MV | C82: RK32383 | D82: 46275.877 | E82: 1003 | F82: 84.3 | G82: 7.584507 | H82: 46298.591 | I82: 2101 | J82: 87.02 | K82: 4.5492958 | L82: =J82-F82 -> 2.72 | M82: =K82-G82 -> -3.0352113
